<?xml version="1.0"?>
<robot name="uiabot_mini">

  <!-- Links -->
  <link name="base_link">
    <visual>
      <geometry>
        <mesh filename="package://uiabot_mini_description/meshes/base_link.STL"/>
      </geometry>
      <origin xyz="0 0 0" rpy="0 0 0"/>
      <material name="gray">
        <color rgba="0.6 0.6 0.6 1.0"/>
      </material>
    </visual>
  </link>

  
  <link name="wheel_right_link">
    <visual>
      <geometry>
        <mesh filename="package://uiabot_mini_description/meshes/wheel.STL"/>
      </geometry>
      <origin xyz="0 0 0" rpy="3.141592653589793 0 0"/>
      <material name="blue">
        <color rgba="0 0 1 1"/>
      </material>
    </visual>
  </link>

<link name="wheel_left_link">
    <visual>
      <geometry>
        <mesh filename="package://uiabot_mini_description/meshes/wheel.STL"/>
      </geometry>
      <origin xyz="0 0 0" rpy="0 0 0"/>
      <material name="blue">
        <color rgba="0 0 1 1"/>
      </material>
    </visual>
  </link>

  <joint name="joint_wheel_right" type="continuous">
    <parent link="base_link"/>
    <child link="wheel_right_link"/>
    <origin xyz="0.00060024 -0.09875  0.0339981720062555 " rpy="-1.5707963267948966 0 0"/>
    <axis xyz="0 0 1"/>
  </joint>

  <joint name="joint_wheel_left" type="continuous">
    <parent link="base_link"/>
    <child link="wheel_left_link"/>
    <origin xyz="0.00060024 0.09875 0.0339981720062555" rpy="-1.5707963267948966 0 0"/>
    <axis xyz="0 0 1"/>
  </joint>


  <!-- IMU (BNO055) Link -->
  <link name="bno055">
    <visual>
      <geometry>
        <box size="0.01 0.01 0.005"/>
      </geometry>
      <material name="green">
        <color rgba="0 1 0 1"/>
      </material>
    </visual>
  </link>

  <joint name="joint_bno055" type="fixed">
    <parent link="base_link"/>
    <child link="bno055"/>
    <origin xyz="-71.75e-3 -58.75e-3 110.35e-3" rpy="0 0 0"/>
  </joint>

  <!-- Laser (RPLidar A1) Link -->
  <link name="laser">
    <visual>
      <geometry>
        <cylinder radius="0.035" length="0.04"/>
      </geometry>
      <material name="black">
        <color rgba="0 0 0 1"/>
      </material>
    </visual>
  </link>

  <joint name="joint_laser" type="fixed">
    <parent link="base_link"/>
    <child link="laser"/>
    <origin xyz="-49.66e-3 0.0 166.5e-3" rpy="0 0 0"/>
  </joint>

</robot>
