<sdf version='1.10'>
  <world name='car_world'>
    <physics name='1ms' type='ignored'>
      <max_step_size>0.001</max_step_size>
      <real_time_factor>1</real_time_factor>
      <real_time_update_rate>1000</real_time_update_rate>
    </physics>
    <plugin name='gz::sim::systems::Physics' filename='gz-sim-physics-system'/>
    <plugin name='gz::sim::systems::UserCommands' filename='gz-sim-user-commands-system'/>
    <plugin name='gz::sim::systems::SceneBroadcaster' filename='gz-sim-scene-broadcaster-system'/>
    <plugin name='gz::sim::systems::Sensors' filename='gz-sim-sensors-system'>
      <render_engine>ogre2</render_engine>
    </plugin>
    <plugin name='gz::sim::systems::Imu' filename='gz-sim-imu-system'/>
    <gravity>0 0 -9.8000000000000007</gravity>
    <magnetic_field>5.5644999999999998e-06 2.2875799999999999e-05 -4.2388400000000002e-05</magnetic_field>
    <atmosphere type='adiabatic'/>
    <scene>
      <ambient>0.400000006 0.400000006 0.400000006 1</ambient>
      <background>0.699999988 0.699999988 0.699999988 1</background>
      <shadows>true</shadows>
    </scene>
    <model name='ground_plane'>
      <static>true</static>
      <link name='link'>
        <collision name='collision'>
          <geometry>
            <plane>
              <normal>0 0 1</normal>
              <size>1 1</size>
            </plane>
          </geometry>
          <surface>
            <friction>
              <ode/>
            </friction>
            <bounce/>
            <contact/>
          </surface>
        </collision>
        <visual name='visual'>
          <geometry>
            <plane>
              <normal>0 0 1</normal>
              <size>100 100</size>
            </plane>
          </geometry>
          <material>
            <ambient>0.800000012 0.800000012 0.800000012 1</ambient>
            <diffuse>0.800000012 0.800000012 0.800000012 1</diffuse>
            <specular>0.800000012 0.800000012 0.800000012 1</specular>
          </material>
        </visual>
        <pose>0 0 0 0 0 0</pose>
        <inertial>
          <pose>0 0 0 0 0 0</pose>
          <mass>1</mass>
          <inertia>
            <ixx>1</ixx>
            <ixy>0</ixy>
            <ixz>0</ixz>
            <iyy>1</iyy>
            <iyz>0</iyz>
            <izz>1</izz>
          </inertia>
        </inertial>
        <enable_wind>false</enable_wind>
      </link>
      <pose>0 0 0 0 0 0</pose>
      <self_collide>false</self_collide>
    </model>
    <model name='uiabot_mini'>
      <link name='base_link'>
        <inertial>
          <pose>-0.0038199391833188541 -5.1042571676802783e-05 0.014098913987836661 0 0 0</pose>
          <mass>1.151</mass>
          <inertia>
            <ixx>0.0122718067498914</ixx>
            <ixy>-3.9908910729800163e-06</ixy>
            <ixz>4.2591962423979148e-05</ixz>
            <iyy>0.012630823431038231</iyy>
            <iyz>5.6547513032145963e-06</iyz>
            <izz>0.010575913808644659</izz>
          </inertia>
        </inertial>
        <collision name='base_link_collision'>
          <pose>0 0 0.050000000000000003 0 0 0</pose>
          <geometry>
            <box>
              <size>0.14999999999999999 0.12 0.059999999999999998</size>
            </box>
          </geometry>
          <surface>
            <friction>
              <ode/>
            </friction>
            <bounce/>
            <contact/>
          </surface>
        </collision>
        <collision name='base_link_fixed_joint_lump__caster_link_collision_1'>
          <pose>-0.086499999999999994 0 0.022349999999999998 0 0 0</pose>
          <geometry>
            <sphere>
              <radius>0.019</radius>
            </sphere>
          </geometry>
          <surface>
            <contact>
              <ode>
                <kp>1000</kp>
                <kd>1</kd>
                <max_vel>0.01</max_vel>
                <min_depth>1.0000000000000001e-05</min_depth>
              </ode>
            </contact>
            <friction>
              <ode>
                <mu>0.10000000000000001</mu>
                <mu2>0.10000000000000001</mu2>
              </ode>
            </friction>
            <bounce/>
          </surface>
        </collision>
        <visual name='base_link_visual'>
          <pose>0 0 0 0 0 0</pose>
          <geometry>
            <mesh>
              <scale>1 1 1</scale>
              <uri>model://uiabot_mini_description/meshes/base_link.STL</uri>
            </mesh>
          </geometry>
          <material>
            <diffuse>0.75000006 0.75000006 0.75000006 1</diffuse>
            <ambient>0.75000006 0.75000006 0.75000006 1</ambient>
          </material>
        </visual>
        <visual name='base_link_fixed_joint_lump__caster_link_visual_1'>
          <pose>-0.086499999999999994 0 0.022349999999999998 0 0 0</pose>
          <geometry>
            <sphere>
              <radius>0.019</radius>
            </sphere>
          </geometry>
          <material>
            <diffuse>0.625 0.625 0.625 1</diffuse>
            <ambient>0.625 0.625 0.625 1</ambient>
          </material>
        </visual>
        <visual name='base_link_fixed_joint_lump__lidar_link_visual_2'>
          <pose>0 0 0.14999999999999999 0 0 3.14159265358979</pose>
          <geometry>
            <cylinder>
              <length>0.040000000000000001</length>
              <radius>0.029999999999999999</radius>
            </cylinder>
          </geometry>
          <material>
            <diffuse>0 0 0 1</diffuse>
            <ambient>0 0 0 1</ambient>
          </material>
        </visual>
        <sensor name='imu_sensor' type='imu'>
          <pose>-0.071749999999999994 -0.058749999999999997 0.11035 0 0 0</pose>
          <topic>imu</topic>
          <update_rate>100</update_rate>
          <enable_metrics>false</enable_metrics>
          <imu>
            <orientation_reference_frame>
              <localization>CUSTOM</localization>
              <custom_rpy>0 0 0</custom_rpy>
              <grav_dir_x>1 0 0</grav_dir_x>
            </orientation_reference_frame>
            <angular_velocity>
              <x>
                <noise type='gaussian'>
                  <mean>0</mean>
                  <stddev>0.00020000000000000001</stddev>
                  <bias_mean>0</bias_mean>
                  <bias_stddev>0</bias_stddev>
                  <dynamic_bias_stddev>0</dynamic_bias_stddev>
                  <dynamic_bias_correlation_time>0</dynamic_bias_correlation_time>
                  <precision>0</precision>
                </noise>
              </x>
              <y>
                <noise type='gaussian'>
                  <mean>0</mean>
                  <stddev>0.00020000000000000001</stddev>
                  <bias_mean>0</bias_mean>
                  <bias_stddev>0</bias_stddev>
                  <dynamic_bias_stddev>0</dynamic_bias_stddev>
                  <dynamic_bias_correlation_time>0</dynamic_bias_correlation_time>
                  <precision>0</precision>
                </noise>
              </y>
              <z>
                <noise type='gaussian'>
                  <mean>0</mean>
                  <stddev>0.00020000000000000001</stddev>
                  <bias_mean>0</bias_mean>
                  <bias_stddev>0</bias_stddev>
                  <dynamic_bias_stddev>0</dynamic_bias_stddev>
                  <dynamic_bias_correlation_time>0</dynamic_bias_correlation_time>
                  <precision>0</precision>
                </noise>
              </z>
            </angular_velocity>
            <linear_acceleration>
              <x>
                <noise type='gaussian'>
                  <mean>0</mean>
                  <stddev>0.017000000000000001</stddev>
                  <bias_mean>0</bias_mean>
                  <bias_stddev>0</bias_stddev>
                  <dynamic_bias_stddev>0</dynamic_bias_stddev>
                  <dynamic_bias_correlation_time>0</dynamic_bias_correlation_time>
                  <precision>0</precision>
                </noise>
              </x>
              <y>
                <noise type='gaussian'>
                  <mean>0</mean>
                  <stddev>0.017000000000000001</stddev>
                  <bias_mean>0</bias_mean>
                  <bias_stddev>0</bias_stddev>
                  <dynamic_bias_stddev>0</dynamic_bias_stddev>
                  <dynamic_bias_correlation_time>0</dynamic_bias_correlation_time>
                  <precision>0</precision>
                </noise>
              </y>
              <z>
                <noise type='gaussian'>
                  <mean>0</mean>
                  <stddev>0.017000000000000001</stddev>
                  <bias_mean>0</bias_mean>
                  <bias_stddev>0</bias_stddev>
                  <dynamic_bias_stddev>0</dynamic_bias_stddev>
                  <dynamic_bias_correlation_time>0</dynamic_bias_correlation_time>
                  <precision>0</precision>
                </noise>
              </z>
            </linear_acceleration>
            <enable_orientation>true</enable_orientation>
          </imu>
        </sensor>
        <sensor name='lidar' type='gpu_lidar'>
          <pose>0 0 0.14999999999999999 0 0 3.1415899999999999</pose>
          <topic>lidar</topic>
          <update_rate>10</update_rate>
          <enable_metrics>false</enable_metrics>
          <lidar>
            <scan>
              <horizontal>
                <samples>360</samples>
                <resolution>1</resolution>
                <min_angle>0</min_angle>
                <max_angle>6.2831900000000003</max_angle>
              </horizontal>
              <vertical>
                <samples>1</samples>
                <min_angle>0</min_angle>
                <max_angle>0</max_angle>
                <resolution>1</resolution>
              </vertical>
            </scan>
            <range>
              <min>0.12</min>
              <max>12</max>
              <resolution>0.01</resolution>
            </range>
            <noise>
              <type>gaussian</type>
              <mean>0</mean>
              <stddev>0.01</stddev>
            </noise>
            <visibility_mask>4294967295</visibility_mask>
          </lidar>
        </sensor>
        <pose>0 0 0 0 0 0</pose>
        <enable_wind>false</enable_wind>
      </link>
      <joint name='wheel_l_joint' type='revolute'>
        <pose>0 0 0 0 0 0</pose>
        <parent>base_link</parent>
        <child>wheel_l_link</child>
        <axis>
          <xyz>0 0 1</xyz>
          <limit>
            <lower>-inf</lower>
            <upper>inf</upper>
            <effort>inf</effort>
            <velocity>inf</velocity>
            <stiffness>100000000</stiffness>
            <dissipation>1</dissipation>
          </limit>
          <dynamics>
            <spring_reference>0</spring_reference>
            <spring_stiffness>0</spring_stiffness>
            <damping>0</damping>
            <friction>0</friction>
          </dynamics>
        </axis>
      </joint>
      <link name='wheel_l_link'>
        <pose>0.0059999995564431691 0.098749985791086681 0.034000091387194661 -1.5707958531776107 6.6133080643591895e-09 3.3266645883386029e-09</pose>
        <inertial>
          <pose>0 0 0 0 0 0</pose>
          <mass>0.10000000000000001</mass>
          <inertia>
            <ixx>0.001</ixx>
            <ixy>0</ixy>
            <ixz>0</ixz>
            <iyy>0.001</iyy>
            <iyz>0</iyz>
            <izz>0.001</izz>
          </inertia>
        </inertial>
        <collision name='wheel_l_link_collision'>
          <pose>0 0 0 0 0 0</pose>
          <geometry>
            <cylinder>
              <length>0.02</length>
              <radius>0.029999999999999999</radius>
            </cylinder>
          </geometry>
          <surface>
            <contact>
              <ode>
                <kp>1000000000</kp>
                <kd>1</kd>
                <max_vel>0.01</max_vel>
                <min_depth>1.0000000000000001e-05</min_depth>
              </ode>
            </contact>
            <friction>
              <ode>
                <mu>1</mu>
                <mu2>1</mu2>
                <fdir1>0 1 0</fdir1>
              </ode>
            </friction>
            <bounce/>
          </surface>
        </collision>
        <visual name='wheel_l_link_visual'>
          <pose>0 0 0 0 0 0</pose>
          <geometry>
            <mesh>
              <scale>1 1 1</scale>
              <uri>model://uiabot_mini_description/meshes/wheel.STL</uri>
            </mesh>
          </geometry>
          <material>
            <diffuse>0.25 0.25 0.25 1</diffuse>
            <ambient>0.25 0.25 0.25 1</ambient>
          </material>
        </visual>
        <enable_wind>false</enable_wind>
      </link>
      <joint name='wheel_r_joint' type='revolute'>
        <pose>0 1.3877799999999999e-17 -1.3877799999999999e-17 0 0 0</pose>
        <parent>base_link</parent>
        <child>wheel_r_link</child>
        <axis>
          <xyz>0 0 1</xyz>
          <limit>
            <lower>-inf</lower>
            <upper>inf</upper>
            <effort>inf</effort>
            <velocity>inf</velocity>
            <stiffness>100000000</stiffness>
            <dissipation>1</dissipation>
          </limit>
          <dynamics>
            <spring_reference>0</spring_reference>
            <spring_stiffness>0</spring_stiffness>
            <damping>0</damping>
            <friction>0</friction>
          </dynamics>
        </axis>
      </joint>
      <link name='wheel_r_link'>
        <pose>0.0060000002134588063 -0.098750014208891193 0.033999997847779968 -1.5707958531776101 6.6129841726844838e-09 3.3266645883769001e-09</pose>
        <inertial>
          <pose>0 0 0 0 0 0</pose>
          <mass>0.10000000000000001</mass>
          <inertia>
            <ixx>0.001</ixx>
            <ixy>0</ixy>
            <ixz>0</ixz>
            <iyy>0.001</iyy>
            <iyz>0</iyz>
            <izz>0.001</izz>
          </inertia>
        </inertial>
        <collision name='wheel_r_link_collision'>
          <pose>0 0 0 0 0 0</pose>
          <geometry>
            <cylinder>
              <length>0.02</length>
              <radius>0.029999999999999999</radius>
            </cylinder>
          </geometry>
          <surface>
            <contact>
              <ode>
                <kp>1000000000</kp>
                <kd>1</kd>
                <max_vel>0.01</max_vel>
                <min_depth>1.0000000000000001e-05</min_depth>
              </ode>
            </contact>
            <friction>
              <ode>
                <mu>1</mu>
                <mu2>1</mu2>
                <fdir1>0 1 0</fdir1>
              </ode>
            </friction>
            <bounce/>
          </surface>
        </collision>
        <visual name='wheel_r_link_visual'>
          <pose>0 0 0 3.14159265358979 0 0</pose>
          <geometry>
            <mesh>
              <scale>1 1 1</scale>
              <uri>model://uiabot_mini_description/meshes/wheel.STL</uri>
            </mesh>
          </geometry>
          <material>
            <diffuse>0.25 0.25 0.25 1</diffuse>
            <ambient>0.25 0.25 0.25 1</ambient>
          </material>
        </visual>
        <enable_wind>false</enable_wind>
      </link>
      <plugin name='gz::sim::systems::JointStatePublisher' filename='gz-sim-joint-state-publisher-system'>
        <topic>joint_states</topic>
      </plugin>
      <plugin name='gz::sim::systems::DiffDrive' filename='gz-sim-diff-drive-system'>
        <left_joint>wheel_l_joint</left_joint>
        <right_joint>wheel_r_joint</right_joint>
        <wheel_separation>0.1975</wheel_separation>
        <wheel_radius>0.03</wheel_radius>
        <odom_publish_frequency>30</odom_publish_frequency>
        <topic>cmd_vel</topic>
        <odom_topic>odom</odom_topic>
        <tf_topic>tf</tf_topic>
        <frame_id>odom</frame_id>
        <child_frame_id>base_link</child_frame_id>
      </plugin>
      <frame name='caster_joint' attached_to='base_link'>
        <pose>-0.086499999999999994 0 0.022349999999999998 0 0 0</pose>
      </frame>
      <frame name='caster_link' attached_to='caster_joint'>
        <pose>0 0 0 0 0 0</pose>
      </frame>
      <frame name='imu_fixed_joint' attached_to='base_link'>
        <pose>-0.071749999999999994 -0.058749999999999997 0.11035 0 0 0</pose>
      </frame>
      <frame name='bno055' attached_to='imu_fixed_joint'>
        <pose>0 0 0 0 0 0</pose>
      </frame>
      <frame name='lidar_fixed_joint' attached_to='base_link'>
        <pose>0 0 0.14999999999999999 0 0 3.14159265358979</pose>
      </frame>
      <frame name='lidar_link' attached_to='lidar_fixed_joint'>
        <pose>0 0 0 0 0 0</pose>
      </frame>
      <pose>-0.00092909921426849104 -1.562302246636604e-05 -0.003957095604671875 -7.8502418225646331e-07 0.0070239929861381006 -0.00018496180900124621</pose>
      <static>false</static>
      <self_collide>false</self_collide>
    </model>
    <include>
      <uri>file:///home/stian/ros2_ws/src/uiabot_mini_gazebo/worlds</uri>
      <name>room_with_walls_10x10</name>
      <pose>-0.38585935791996739 1.5008772745082206 0 0 0 0</pose>
    </include>
  </world>
</sdf>
